<mujoco model="plane">
  <compiler angle="radian"/>

  <size nkey="1"/>

  <visual>
    <global azimuth="150" elevation="-20"/>
    <headlight ambient="0.3 0.3 0.3" diffuse="0.6 0.6 0.6" specular="0 0 0"/>
    <rgba haze="0.15 0.25 0.35 1"/>
  </visual>

  <statistic extent="1.1" center="0 0 0.55"/>

  <default>
    <default class="panda:0main">
      <default class="panda:0panda">
        <material shininess="0.25"/>
        <joint range="-2.8973 2.8973" armature="0.1" damping="1"/>
        <general ctrlrange="-2.8973 2.8973" forcerange="-87 87" biastype="affine"/>
        <default class="panda:0finger">
          <joint type="slide" range="0 0.04"/>
        </default>
        <default class="panda:0visual">
          <geom type="mesh" contype="0" conaffinity="0" group="2"/>
        </default>
        <default class="panda:0collision">
          <geom type="mesh" group="3"/>
          <default class="panda:0fingertip_pad_collision_1">
            <geom size="0.0085 0.004 0.0085" type="box"/>
          </default>
          <default class="panda:0fingertip_pad_collision_2">
            <geom size="0.003 0.002 0.003" type="box"/>
          </default>
          <default class="panda:0fingertip_pad_collision_3">
            <geom size="0.003 0.002 0.003" type="box"/>
          </default>
          <default class="panda:0fingertip_pad_collision_4">
            <geom size="0.003 0.002 0.0035" type="box"/>
          </default>
          <default class="panda:0fingertip_pad_collision_5">
            <geom size="0.003 0.002 0.0035" type="box"/>
          </default>
        </default>
      </default>
    </default>
  </default>

  <asset>
    <texture type="skybox" builtin="gradient" rgb1="0.3 0.5 0.7" rgb2="0 0 0" width="512" height="3072"/>
    <texture type="2d" name="groundplane" builtin="checker" mark="edge" rgb1="0.2 0.3 0.4" rgb2="0.1 0.2 0.3" markrgb="0.8 0.8 0.8" width="300" height="300"/>
    <material name="groundplane" texture="groundplane" texuniform="true" texrepeat="5 5" reflectance="0.2"/>
    <material name="panda:0white" class="panda:0panda"/>
    <material name="panda:0off_white" class="panda:0panda" rgba="0.901961 0.921569 0.929412 1"/>
    <material name="panda:0black" class="panda:0panda" rgba="0.25 0.25 0.25 1"/>
    <material name="panda:0green" class="panda:0panda" rgba="0 1 0 1"/>
    <material name="panda:0light_blue" class="panda:0panda" rgba="0.039216 0.541176 0.780392 1"/>
    <mesh name="panda:0link0_c" file="link0.stl"/>
    <mesh name="panda:0link1_c" file="link1.stl"/>
    <mesh name="panda:0link2_c" file="link2.stl"/>
    <mesh name="panda:0link3_c" file="link3.stl"/>
    <mesh name="panda:0link4_c" file="link4.stl"/>
    <mesh name="panda:0link5_c0" file="link5_collision_0.obj"/>
    <mesh name="panda:0link5_c1" file="link5_collision_1.obj"/>
    <mesh name="panda:0link5_c2" file="link5_collision_2.obj"/>
    <mesh name="panda:0link6_c" file="link6.stl"/>
    <mesh name="panda:0link7_c" file="link7.stl"/>
    <mesh name="panda:0hand_c" file="hand.stl"/>
    <mesh name="panda:0link0_0" file="link0_0.obj"/>
    <mesh name="panda:0link0_1" file="link0_1.obj"/>
    <mesh name="panda:0link0_2" file="link0_2.obj"/>
    <mesh name="panda:0link0_3" file="link0_3.obj"/>
    <mesh name="panda:0link0_4" file="link0_4.obj"/>
    <mesh name="panda:0link0_5" file="link0_5.obj"/>
    <mesh name="panda:0link0_7" file="link0_7.obj"/>
    <mesh name="panda:0link0_8" file="link0_8.obj"/>
    <mesh name="panda:0link0_9" file="link0_9.obj"/>
    <mesh name="panda:0link0_10" file="link0_10.obj"/>
    <mesh name="panda:0link0_11" file="link0_11.obj"/>
    <mesh name="panda:0link1" file="link1.obj"/>
    <mesh name="panda:0link2" file="link2.obj"/>
    <mesh name="panda:0link3_0" file="link3_0.obj"/>
    <mesh name="panda:0link3_1" file="link3_1.obj"/>
    <mesh name="panda:0link3_2" file="link3_2.obj"/>
    <mesh name="panda:0link3_3" file="link3_3.obj"/>
    <mesh name="panda:0link4_0" file="link4_0.obj"/>
    <mesh name="panda:0link4_1" file="link4_1.obj"/>
    <mesh name="panda:0link4_2" file="link4_2.obj"/>
    <mesh name="panda:0link4_3" file="link4_3.obj"/>
    <mesh name="panda:0link5_0" file="link5_0.obj"/>
    <mesh name="panda:0link5_1" file="link5_1.obj"/>
    <mesh name="panda:0link5_2" file="link5_2.obj"/>
    <mesh name="panda:0link6_0" file="link6_0.obj"/>
    <mesh name="panda:0link6_1" file="link6_1.obj"/>
    <mesh name="panda:0link6_2" file="link6_2.obj"/>
    <mesh name="panda:0link6_3" file="link6_3.obj"/>
    <mesh name="panda:0link6_4" file="link6_4.obj"/>
    <mesh name="panda:0link6_5" file="link6_5.obj"/>
    <mesh name="panda:0link6_6" file="link6_6.obj"/>
    <mesh name="panda:0link6_7" file="link6_7.obj"/>
    <mesh name="panda:0link6_8" file="link6_8.obj"/>
    <mesh name="panda:0link6_9" file="link6_9.obj"/>
    <mesh name="panda:0link6_10" file="link6_10.obj"/>
    <mesh name="panda:0link6_11" file="link6_11.obj"/>
    <mesh name="panda:0link6_12" file="link6_12.obj"/>
    <mesh name="panda:0link6_13" file="link6_13.obj"/>
    <mesh name="panda:0link6_14" file="link6_14.obj"/>
    <mesh name="panda:0link6_15" file="link6_15.obj"/>
    <mesh name="panda:0link6_16" file="link6_16.obj"/>
    <mesh name="panda:0link7_0" file="link7_0.obj"/>
    <mesh name="panda:0link7_1" file="link7_1.obj"/>
    <mesh name="panda:0link7_2" file="link7_2.obj"/>
    <mesh name="panda:0link7_3" file="link7_3.obj"/>
    <mesh name="panda:0link7_4" file="link7_4.obj"/>
    <mesh name="panda:0link7_5" file="link7_5.obj"/>
    <mesh name="panda:0link7_6" file="link7_6.obj"/>
    <mesh name="panda:0link7_7" file="link7_7.obj"/>
    <mesh name="panda:0hand_0" file="hand_0.obj"/>
    <mesh name="panda:0hand_1" file="hand_1.obj"/>
    <mesh name="panda:0hand_2" file="hand_2.obj"/>
    <mesh name="panda:0hand_3" file="hand_3.obj"/>
    <mesh name="panda:0hand_4" file="hand_4.obj"/>
    <mesh name="panda:0finger_0" file="finger_0.obj"/>
    <mesh name="panda:0finger_1" file="finger_1.obj"/>
  </asset>

  <worldbody>
    <geom name="floor" size="0 0 0.125" type="plane" conaffinity="15" material="groundplane"/>
    <light pos="0 0 3" dir="0 0 -1"/>
    <body name="support_body" quat="0.707107 0 0 -0.707107">
      <body name="panda:0world">
        <light name="panda:0top" pos="0 0 2" dir="0 0 -1" mode="trackcom"/>
        <body name="panda:0link0" childclass="panda:0panda">
          <inertial pos="-0.041018 -0.00014 0.049974" quat="0.00630474 0.751245 0.00741774 0.659952" mass="0.629769" diaginertia="0.00430465 0.00387984 0.00313051"/>
          <geom class="panda:0visual" material="panda:0off_white" mesh="panda:0link0_0"/>
          <geom class="panda:0visual" material="panda:0black" mesh="panda:0link0_1"/>
          <geom class="panda:0visual" material="panda:0off_white" mesh="panda:0link0_2"/>
          <geom class="panda:0visual" material="panda:0black" mesh="panda:0link0_3"/>
          <geom class="panda:0visual" material="panda:0off_white" mesh="panda:0link0_4"/>
          <geom class="panda:0visual" material="panda:0black" mesh="panda:0link0_5"/>
          <geom class="panda:0visual" material="panda:0white" mesh="panda:0link0_7"/>
          <geom class="panda:0visual" material="panda:0white" mesh="panda:0link0_8"/>
          <geom class="panda:0visual" material="panda:0black" mesh="panda:0link0_9"/>
          <geom class="panda:0visual" material="panda:0off_white" mesh="panda:0link0_10"/>
          <geom class="panda:0visual" material="panda:0white" mesh="panda:0link0_11"/>
          <geom class="panda:0collision" mesh="panda:0link0_c"/>
          <body name="panda:0link1" pos="0 0 0.333">
            <inertial pos="0.003875 0.002081 -0.04762" quat="0.711549 0.00634377 -0.0131124 0.702485" mass="4.97068" diaginertia="0.707137 0.703435 0.00852456"/>
            <joint name="panda:0joint1" pos="0 0 0" axis="0 0 1"/>
            <geom class="panda:0visual" material="panda:0white" mesh="panda:0link1"/>
            <geom class="panda:0collision" mesh="panda:0link1_c"/>
            <body name="panda:0link2" quat="0.707107 -0.707107 0 0">
              <inertial pos="-0.003141 -0.02872 0.003495" quat="-0.168175 0.828366 -0.122878 0.520027" mass="0.646926" diaginertia="0.0310326 0.0283001 0.00273425"/>
              <joint name="panda:0joint2" pos="0 0 0" axis="0 0 1" range="-1.7628 1.7628"/>
              <geom class="panda:0visual" material="panda:0white" mesh="panda:0link2"/>
              <geom class="panda:0collision" mesh="panda:0link2_c"/>
              <body name="panda:0link3" pos="0 -0.316 0" quat="0.707107 0.707107 0 0">
                <inertial pos="0.027518 0.039252 -0.066502" quat="0.662769 -0.00678331 0.252053 0.705096" mass="3.2286" diaginertia="0.0415014 0.0414793 0.00124635"/>
                <joint name="panda:0joint3" pos="0 0 0" axis="0 0 1"/>
                <geom class="panda:0visual" material="panda:0white" mesh="panda:0link3_0"/>
                <geom class="panda:0visual" material="panda:0white" mesh="panda:0link3_1"/>
                <geom class="panda:0visual" material="panda:0white" mesh="panda:0link3_2"/>
                <geom class="panda:0visual" material="panda:0black" mesh="panda:0link3_3"/>
                <geom class="panda:0collision" mesh="panda:0link3_c"/>
                <body name="panda:0link4" pos="0.0825 0 0" quat="0.707107 0.707107 0 0">
                  <inertial pos="-0.05317 0.104419 0.027454" quat="0.65058 0.529822 -0.0962034 0.535518" mass="3.5879" diaginertia="0.0349596 0.0281483 0.0106201"/>
                  <joint name="panda:0joint4" pos="0 0 0" axis="0 0 1" range="-3.0718 -0.0698"/>
                  <geom class="panda:0visual" material="panda:0white" mesh="panda:0link4_0"/>
                  <geom class="panda:0visual" material="panda:0white" mesh="panda:0link4_1"/>
                  <geom class="panda:0visual" material="panda:0black" mesh="panda:0link4_2"/>
                  <geom class="panda:0visual" material="panda:0white" mesh="panda:0link4_3"/>
                  <geom class="panda:0collision" mesh="panda:0link4_c"/>
                  <body name="panda:0link5" pos="-0.0825 0.384 0" quat="0.707107 -0.707107 0 0">
                    <inertial pos="-0.011953 0.041065 -0.038437" quat="0.987313 -0.0121954 0.0719187 -0.141037" mass="1.22595" diaginertia="0.0367625 0.0288531 0.00803437"/>
                    <joint name="panda:0joint5" pos="0 0 0" axis="0 0 1"/>
                    <geom class="panda:0visual" material="panda:0black" mesh="panda:0link5_0"/>
                    <geom class="panda:0visual" material="panda:0white" mesh="panda:0link5_1"/>
                    <geom class="panda:0visual" material="panda:0white" mesh="panda:0link5_2"/>
                    <geom class="panda:0collision" mesh="panda:0link5_c0"/>
                    <geom class="panda:0collision" mesh="panda:0link5_c1"/>
                    <geom class="panda:0collision" mesh="panda:0link5_c2"/>
                    <body name="panda:0link6" quat="0.707107 0.707107 0 0">
                      <inertial pos="0.060149 -0.014117 -0.010517" quat="0.101075 0.59332 0.0287227 0.798079" mass="1.66656" diaginertia="0.00584276 0.00431037 0.00159787"/>
                      <joint name="panda:0joint6" pos="0 0 0" axis="0 0 1" range="-0.0175 3.7525"/>
                      <geom class="panda:0visual" material="panda:0off_white" mesh="panda:0link6_0"/>
                      <geom class="panda:0visual" material="panda:0white" mesh="panda:0link6_1"/>
                      <geom class="panda:0visual" material="panda:0black" mesh="panda:0link6_2"/>
                      <geom class="panda:0visual" material="panda:0white" mesh="panda:0link6_3"/>
                      <geom class="panda:0visual" material="panda:0white" mesh="panda:0link6_4"/>
                      <geom class="panda:0visual" material="panda:0white" mesh="panda:0link6_5"/>
                      <geom class="panda:0visual" material="panda:0white" mesh="panda:0link6_6"/>
                      <geom class="panda:0visual" material="panda:0light_blue" mesh="panda:0link6_7"/>
                      <geom class="panda:0visual" material="panda:0light_blue" mesh="panda:0link6_8"/>
                      <geom class="panda:0visual" material="panda:0black" mesh="panda:0link6_9"/>
                      <geom class="panda:0visual" material="panda:0black" mesh="panda:0link6_10"/>
                      <geom class="panda:0visual" material="panda:0white" mesh="panda:0link6_11"/>
                      <geom class="panda:0visual" material="panda:0green" mesh="panda:0link6_12"/>
                      <geom class="panda:0visual" material="panda:0white" mesh="panda:0link6_13"/>
                      <geom class="panda:0visual" material="panda:0black" mesh="panda:0link6_14"/>
                      <geom class="panda:0visual" material="panda:0black" mesh="panda:0link6_15"/>
                      <geom class="panda:0visual" material="panda:0white" mesh="panda:0link6_16"/>
                      <geom class="panda:0collision" mesh="panda:0link6_c"/>
                      <body name="panda:0link7" pos="0.088 0 0" quat="0.707107 0.707107 0 0">
                        <inertial pos="0.010517 -0.004252 0.061597" quat="0.992939 -0.0762041 0.0733595 -0.0537067" mass="0.735522" diaginertia="0.0127345 0.0101055 0.00451803"/>
                        <joint name="panda:0joint7" pos="0 0 0" axis="0 0 1"/>
                        <geom class="panda:0visual" material="panda:0white" mesh="panda:0link7_0"/>
                        <geom class="panda:0visual" material="panda:0black" mesh="panda:0link7_1"/>
                        <geom class="panda:0visual" material="panda:0black" mesh="panda:0link7_2"/>
                        <geom class="panda:0visual" material="panda:0black" mesh="panda:0link7_3"/>
                        <geom class="panda:0visual" material="panda:0black" mesh="panda:0link7_4"/>
                        <geom class="panda:0visual" material="panda:0black" mesh="panda:0link7_5"/>
                        <geom class="panda:0visual" material="panda:0black" mesh="panda:0link7_6"/>
                        <geom class="panda:0visual" material="panda:0white" mesh="panda:0link7_7"/>
                        <geom class="panda:0collision" mesh="panda:0link7_c"/>
                        <body name="panda:0hand" pos="0 0 0.107" quat="0.92388 0 0 -0.382683">
                          <inertial pos="-0.01 0 0.03" mass="0.73" diaginertia="0.001 0.0025 0.0017"/>
                          <geom class="panda:0visual" material="panda:0off_white" mesh="panda:0hand_0"/>
                          <geom class="panda:0visual" material="panda:0black" mesh="panda:0hand_1"/>
                          <geom class="panda:0visual" material="panda:0black" mesh="panda:0hand_2"/>
                          <geom class="panda:0visual" material="panda:0white" mesh="panda:0hand_3"/>
                          <geom class="panda:0visual" material="panda:0off_white" mesh="panda:0hand_4"/>
                          <geom class="panda:0collision" mesh="panda:0hand_c"/>
                          <body name="panda:0left_finger" pos="0 0 0.0584">
                            <inertial pos="0 0 0" mass="0.015" diaginertia="2.375e-06 2.375e-06 7.5e-07"/>
                            <joint name="panda:0finger_joint1" class="panda:0finger" pos="0 0 0" axis="0 1 0"/>
                            <geom class="panda:0visual" material="panda:0off_white" mesh="panda:0finger_0"/>
                            <geom class="panda:0visual" material="panda:0black" mesh="panda:0finger_1"/>
                            <geom class="panda:0collision" mesh="panda:0finger_0"/>
                            <geom class="panda:0fingertip_pad_collision_1" pos="0 0.0055 0.0445"/>
                            <geom class="panda:0fingertip_pad_collision_2" pos="0.0055 0.002 0.05"/>
                            <geom class="panda:0fingertip_pad_collision_3" pos="-0.0055 0.002 0.05"/>
                            <geom class="panda:0fingertip_pad_collision_4" pos="0.0055 0.002 0.0395"/>
                            <geom class="panda:0fingertip_pad_collision_5" pos="-0.0055 0.002 0.0395"/>
                          </body>
                          <body name="panda:0right_finger" pos="0 0 0.0584" quat="0 0 0 1">
                            <inertial pos="0 0 0" mass="0.015" diaginertia="2.375e-06 2.375e-06 7.5e-07"/>
                            <joint name="panda:0finger_joint2" class="panda:0finger" pos="0 0 0" axis="0 1 0"/>
                            <geom class="panda:0visual" material="panda:0off_white" mesh="panda:0finger_0"/>
                            <geom class="panda:0visual" material="panda:0black" mesh="panda:0finger_1"/>
                            <geom class="panda:0collision" mesh="panda:0finger_0"/>
                            <geom class="panda:0fingertip_pad_collision_1" pos="0 0.0055 0.0445"/>
                            <geom class="panda:0fingertip_pad_collision_2" pos="0.0055 0.002 0.05"/>
                            <geom class="panda:0fingertip_pad_collision_3" pos="-0.0055 0.002 0.05"/>
                            <geom class="panda:0fingertip_pad_collision_4" pos="0.0055 0.002 0.0395"/>
                            <geom class="panda:0fingertip_pad_collision_5" pos="-0.0055 0.002 0.0395"/>
                          </body>
                        </body>
                      </body>
                    </body>
                  </body>
                </body>
              </body>
            </body>
          </body>
        </body>
      </body>
    </body>
  </worldbody>

  <equality>
    <joint joint1="panda:0finger_joint1" joint2="panda:0finger_joint2" polycoef="0 1 0 0 0" solref="0.005" solimp="0.95 0.99"/>
  </equality>

  <tendon>
    <fixed name="panda:0split">
      <joint joint="panda:0finger_joint1" coef="0.5"/>
      <joint joint="panda:0finger_joint2" coef="0.5"/>
    </fixed>
  </tendon>

  <actuator>
    <general name="panda:0actuator1" class="panda:0panda" joint="panda:0joint1" gainprm="4500" biasprm="0 -4500 -450"/>
    <general name="panda:0actuator2" class="panda:0panda" joint="panda:0joint2" ctrlrange="-1.7628 1.7628" gainprm="4500" biasprm="0 -4500 -450"/>
    <general name="panda:0actuator3" class="panda:0panda" joint="panda:0joint3" gainprm="3500" biasprm="0 -3500 -350"/>
    <general name="panda:0actuator4" class="panda:0panda" joint="panda:0joint4" ctrlrange="-3.0718 -0.0698" gainprm="3500" biasprm="0 -3500 -350"/>
    <general name="panda:0actuator5" class="panda:0panda" joint="panda:0joint5" forcerange="-12 12" gainprm="2000" biasprm="0 -2000 -200"/>
    <general name="panda:0actuator6" class="panda:0panda" joint="panda:0joint6" ctrlrange="-0.0175 3.7525" forcerange="-12 12" gainprm="2000" biasprm="0 -2000 -200"/>
    <general name="panda:0actuator7" class="panda:0panda" joint="panda:0joint7" forcerange="-12 12" gainprm="2000" biasprm="0 -2000 -200"/>
    <general name="panda:0actuator8" class="panda:0panda" tendon="panda:0split" ctrlrange="0 255" forcerange="-100 100" gainprm="0.0156863" biasprm="0 -100 -10"/>
  </actuator>

  <keyframe>
    <key name="panda:0home" qpos="0 0 0 -1.57079 0 1.57079 -0.7853 0.04 0.04" ctrl="0 0 0 -1.57079 0 1.57079 -0.7853 255"/>
  </keyframe>
</mujoco>
