<mujoco model="PandaFrame">
  <compiler angle="radian"/>

  <default>
    <default class="pandamain">
      <default class="pandapanda:gripper">
        <joint type="slide" limited="true" range="0 0.04" damping="10"/>
        <geom type="box" condim="4" solimp="0.998 0.999" margin="0.001"/>
      </default>
    </default>
  </default>

  <asset>
    <mesh name="pandalink0v" file="link0v.stl"/>
    <mesh name="pandalink1v" file="link1v.stl"/>
    <mesh name="pandalink2v" file="link2v.stl"/>
    <mesh name="pandalink3v" file="link3v.stl"/>
    <mesh name="pandalink4v" file="link4v.stl"/>
    <mesh name="pandalink5v" file="link5v.stl"/>
    <mesh name="pandalink6v" file="link6v.stl"/>
    <mesh name="pandalink7v" file="link7v.stl"/>
    <mesh name="pandahandv" file="handv.stl"/>
    <mesh name="pandafingerv" file="fingerv.stl"/>
  </asset>

  <worldbody>
    <body name="table_plane" pos="0.2 0 -0.02">
      <geom size="0.49 0.98 0.001" type="box" solref="0.002" solimp="0.999 0.999" rgba="0.8 0.655 0.45 1"/>
      <body name="panda_ground" pos="-0.24 0 0.01">
        <geom size="0.18 0.18 0.01" type="box" rgba="0.9 0.9 0.9 1"/>
      </body>
      <body name="front_upper" pos="0.49 0 -0.02">
        <geom size="0.02 0.96 0.02" type="box" rgba="0.9 0.9 0.9 1"/>
      </body>
      <body name="front_mid" pos="0.49 0 -0.445">
        <geom size="0.02 0.96 0.02" type="box" rgba="0.9 0.9 0.9 1"/>
      </body>
      <body name="front_lower" pos="0.49 0 -0.87">
        <geom size="0.02 0.96 0.02" type="box" rgba="0.9 0.9 0.9 1"/>
      </body>
      <body name="back_upper" pos="-0.49 0 -0.02">
        <geom size="0.02 0.96 0.02" type="box" rgba="0.9 0.9 0.9 1"/>
      </body>
      <body name="back_mid" pos="-0.49 0 -0.445">
        <geom size="0.02 0.96 0.02" type="box" rgba="0.9 0.9 0.9 1"/>
      </body>
      <body name="back_lower" pos="-0.49 0 -0.87">
        <geom size="0.02 0.96 0.02" type="box" rgba="0.9 0.9 0.9 1"/>
      </body>
      <body name="vert_front_left" pos="0.49 0.98 -0.445">
        <geom size="0.02 0.02 0.445" type="box" rgba="0.9 0.9 0.9 1"/>
      </body>
      <body name="vert_front_right" pos="0.49 -0.98 -0.445">
        <geom size="0.02 0.02 0.445" type="box" rgba="0.9 0.9 0.9 1"/>
      </body>
      <body name="vert_back_left" pos="-0.49 0.98 -0.445">
        <geom size="0.02 0.02 0.445" type="box" rgba="0.9 0.9 0.9 1"/>
      </body>
      <body name="vert_back_right" pos="-0.49 -0.98 -0.445">
        <geom size="0.02 0.02 0.445" type="box" rgba="0.9 0.9 0.9 1"/>
      </body>
      <body name="side_upper_right" pos="0 -0.98 -0.02">
        <geom size="0.47 0.02 0.02" type="box" rgba="0.9 0.9 0.9 1"/>
      </body>
      <body name="side_lower_right" pos="0 -0.98 -0.87">
        <geom size="0.47 0.02 0.02" type="box" rgba="0.9 0.9 0.9 1"/>
      </body>
      <body name="side_upper_left" pos="0 0.98 -0.02">
        <geom size="0.47 0.02 0.02" type="box" rgba="0.9 0.9 0.9 1"/>
      </body>
      <body name="side_lower_left" pos="0 0.98 -0.87">
        <geom size="0.47 0.02 0.02" type="box" rgba="0.9 0.9 0.9 1"/>
      </body>
      <body name="foot_front_left" pos="0.49 0.98 -0.9">
        <geom size="0.02 0.02" type="cylinder" rgba="0 0 0 1"/>
      </body>
      <body name="foot_front_mid" pos="0.49 0 -0.9">
        <geom size="0.02 0.02" type="cylinder" rgba="0 0 0 1"/>
      </body>
      <body name="foot_front_right" pos="0.49 -0.98 -0.9">
        <geom size="0.02 0.02" type="cylinder" rgba="0 0 0 1"/>
      </body>
      <body name="foot_back_left" pos="-0.49 0.98 -0.9">
        <geom size="0.02 0.02" type="cylinder" rgba="0 0 0 1"/>
      </body>
      <body name="foot_back_mid" pos="-0.49 0 -0.9">
        <geom size="0.02 0.02" type="cylinder" rgba="0 0 0 1"/>
      </body>
      <body name="foot_back_right" pos="-0.49 -0.98 -0.9">
        <geom size="0.02 0.02" type="cylinder" rgba="0 0 0 1"/>
      </body>
      <body name="top_back_left" pos="-0.49 0.98 0.65">
        <geom size="0.02 0.02 0.65" type="box" rgba="0.9 0.9 0.9 1"/>
      </body>
      <body name="top_back_right" pos="-0.49 -0.98 0.65">
        <geom size="0.02 0.02 0.65" type="box" rgba="0.9 0.9 0.9 1"/>
      </body>
      <body name="top_front" pos="0.49 0 1.28">
        <geom size="0.02 0.96 0.02" type="box" rgba="0.9 0.9 0.9 1"/>
      </body>
      <body name="top_back" pos="-0.49 0 1.28">
        <geom size="0.02 0.96 0.02" type="box" rgba="0.9 0.9 0.9 1"/>
      </body>
      <body name="top_side_right" pos="0 -0.98 1.28">
        <geom size="0.51 0.02 0.02" type="box" rgba="0.9 0.9 0.9 1"/>
      </body>
      <body name="top_side_mid" pos="0 0 1.28">
        <geom size="0.51 0.02 0.02" type="box" rgba="0.9 0.9 0.9 1"/>
      </body>
      <body name="top_side_left" pos="0 0.98 1.28">
        <geom size="0.51 0.02 0.02" type="box" rgba="0.9 0.9 0.9 1"/>
      </body>
      <body name="rot_lower_right" pos="-0.31 0.98 0.22" quat="0.894427 0 0.447214 0">
        <geom size="0.3 0.02 0.02" type="box" rgba="0.9 0.9 0.9 1"/>
      </body>
      <body name="rot_lower_left" pos="-0.31 -0.98 0.22" quat="0.894427 0 0.447214 0">
        <geom size="0.3 0.02 0.02" type="box" rgba="0.9 0.9 0.9 1"/>
      </body>
      <body name="rot_upper_right" pos="-0.31 0.98 1.04" quat="0.447214 0 0.894427 0">
        <geom size="0.3 0.02 0.02" type="box" rgba="0.9 0.9 0.9 1"/>
      </body>
      <body name="rot_upper_left" pos="-0.31 -0.98 1.04" quat="0.447214 0 0.894427 0">
        <geom size="0.3 0.02 0.02" type="box" rgba="0.9 0.9 0.9 1"/>
      </body>
      <body name="support_body" pos="0 0 -0.4">
        <geom size="0.49 0.98 0.4" type="box" solref="0.002" solimp="0.999 0.999" rgba="0 0 0 0"/>
        <body name="pandaworld">
          <body name="pandapanda_link0">
            <inertial pos="-0.0291898 -0.000879465 0.0566032" quat="0.00411744 0.564916 0.0132875 0.825031" mass="3.01399" diaginertia="0.0126801 0.0117603 0.00856656"/>
            <geom name="pandapanda_link0:geom1" type="mesh" contype="0" conaffinity="0" group="1" rgba="1 1 1 1" mesh="pandalink0v"/>
            <geom name="pandapanda_link0:geom2" type="mesh" rgba="1 1 1 1" mesh="pandalink0v"/>
            <body name="pandapanda_link1" pos="0 0 0.333">
              <inertial pos="1.1399e-05 -0.0312655 -0.0693733" quat="0.98466 0.174481 -0.000101815 0.000347662" mass="2.77281" diaginertia="0.0164224 0.0153969 0.00546286"/>
              <joint name="pandapanda_joint1" pos="0 0 0" axis="0 0 1" limited="true" range="-2.9671 2.9671"/>
              <geom name="pandapanda_joint1:geom1" type="mesh" contype="0" conaffinity="0" group="1" rgba="1 1 1 1" mesh="pandalink1v"/>
              <geom name="pandapanda_joint1:geom2" type="mesh" rgba="1 1 1 1" mesh="pandalink1v"/>
              <body name="pandapanda_link2" quat="0.707107 -0.707107 0 0">
                <inertial pos="-1.31766e-05 -0.0703216 0.0311782" quat="0.57484 0.818266 -6.05764e-05 -6.61626e-05" mass="2.7996" diaginertia="0.016787 0.0157415 0.00553027"/>
                <joint name="pandapanda_joint2" pos="0 0 0" axis="0 0 1" limited="true" range="-1.8326 1.8326"/>
                <geom name="pandapanda_joint2:geom1" type="mesh" contype="0" conaffinity="0" group="1" rgba="1 1 1 1" mesh="pandalink2v"/>
                <geom name="pandapanda_joint2:geom2" type="mesh" rgba="1 1 1 1" mesh="pandalink2v"/>
                <body name="pandapanda_link3" pos="0 -0.316 0" quat="0.707107 0.707107 0 0">
                  <inertial pos="0.0443483 0.0249283 -0.03813" quat="0.0615263 0.349824 0.234291 0.904956" mass="2.14603" diaginertia="0.00915257 0.00896477 0.00384742"/>
                  <joint name="pandapanda_joint3" pos="0 0 0" axis="0 0 1" limited="true" range="-2.9671 2.9671"/>
                  <geom name="pandapanda_joint3:geom1" type="mesh" contype="0" conaffinity="0" group="1" rgba="1 1 1 1" mesh="pandalink3v"/>
                  <geom name="pandapanda_joint3:geom2" type="mesh" rgba="1 1 1 1" mesh="pandalink3v"/>
                  <body name="pandapanda_link4" pos="0.0825 0 0" quat="0.707107 0.707107 0 0">
                    <inertial pos="-0.0385503 0.0395256 0.0247162" quat="0.813566 0.465041 0.309792 0.160858" mass="2.18807" diaginertia="0.00946899 0.00928491 0.00396694"/>
                    <joint name="pandapanda_joint4" pos="0 0 0" axis="0 0 1" limited="true" range="-3.1416 0.0873"/>
                    <geom name="pandapanda_link4:geom1" type="mesh" contype="0" conaffinity="0" group="1" rgba="1 1 1 1" mesh="pandalink4v"/>
                    <geom name="pandapanda_link4:geom2" type="mesh" rgba="1 1 1 1" mesh="pandalink4v"/>
                    <body name="pandapanda_link5" pos="-0.0825 0.384 0" quat="0.707107 -0.707107 0 0">
                      <inertial pos="-6.36776e-05 0.0384124 -0.10997" quat="0.990767 -0.135571 0.000963106 0.000694406" mass="3.19545" diaginertia="0.0278873 0.0268823 0.00569569"/>
                      <joint name="pandapanda_joint5" pos="0 0 0" axis="0 0 1" limited="true" range="-2.9671 2.9671"/>
                      <geom name="pandapanda_link5:geom1" type="mesh" contype="0" conaffinity="0" group="1" rgba="1 1 1 1" mesh="pandalink5v"/>
                      <geom name="pandapanda_link5:geom2" type="mesh" rgba="1 1 1 1" mesh="pandalink5v"/>
                      <body name="pandapanda_link6" quat="0.707107 0.707107 0 0">
                        <inertial pos="0.0510023 0.00693267 0.00616899" quat="-0.0460841 0.754362 0.044494 0.653325" mass="1.35761" diaginertia="0.00412168 0.0033698 0.00213304"/>
                        <joint name="pandapanda_joint6" pos="0 0 0" axis="0 0 1" limited="true" range="-0.0873 3.8223"/>
                        <geom name="pandapanda_link6:geom1" type="mesh" contype="0" conaffinity="0" group="1" rgba="1 1 1 1" mesh="pandalink6v"/>
                        <geom name="pandapanda_link6:geom2" type="mesh" rgba="1 1 1 1" mesh="pandalink6v"/>
                        <body name="pandapanda_link7" pos="0.088 0 0" quat="0.707107 0.707107 0 0">
                          <inertial pos="0.0103614 0.0103596 0.0791078" quat="0.63547 0.278021 -0.670462 0.263369" mass="0.417345" diaginertia="0.000637671 0.000528056 0.000279577"/>
                          <joint name="pandapanda_joint7" pos="0 0 0" axis="0 0 1" limited="true" range="-2.9671 2.9671"/>
                          <geom name="pandapanda_link7:geom1" type="mesh" contype="0" conaffinity="0" group="1" rgba="1 1 1 1" mesh="pandalink7v"/>
                          <geom name="pandapanda_link7:geom2" type="mesh" solimp="1.998 1.999 0" rgba="1 1 1 1" mesh="pandalink7v"/>
                          <body name="pandapanda_link8" pos="0 0 0.107">
                            <inertial pos="0 0 0" mass="0.1" diaginertia="0.1 0.1 0.1"/>
                            <body name="pandapanda_hand" quat="0.92388 0 0 -0.382683">
                              <inertial pos="-2.76618e-06 -0.00061547 0.0239295" quat="0.697945 0.716151 -0.000242485 8.47563e-05" mass="0.670782" diaginertia="0.00227632 0.00206087 0.000456542"/>
                              <geom name="pandapanda_hand:geom1" type="mesh" contype="0" conaffinity="0" group="1" mesh="pandahandv"/>
                              <geom name="pandapanda_hand:geom2" type="mesh" solimp="1.998 1.999 0" mesh="pandahandv"/>
                              <camera name="pandargbd" pos="0.1 0 0" quat="0.000563312 0.706825 0.707388 0.000562864" ipd="0" fovy="60"/>
                              <body name="pandatcp" pos="0 0 0.105">
                                <site name="pandatcp" pos="0 0 0" size="0.001" rgba="0 0 1 0"/>
                              </body>
                              <body name="pandapanda_leftfinger" childclass="pandapanda:gripper" pos="0 0 0.0584">
                                <inertial pos="-2.42335e-05 0.0119585 0.0237816" quat="0.996177 0.0868631 -2.79377e-05 -0.00926642" mass="0.0218754" diaginertia="5.69661e-06 5.56035e-06 1.55183e-06"/>
                                <joint name="pandapanda_finger_joint1" pos="0 0 0" axis="0 1 0"/>
                                <geom name="pandapanda_leftfinger:geom1" type="mesh" contype="0" conaffinity="0" group="1" mesh="pandafingerv"/>
                                <geom name="pandapanda_leftfinger:geom2" type="mesh" mesh="pandafingerv"/>
                                <site name="pandapanda_leftfinger:site" pos="0 0.012 0.045" size="0.012 0.015 0.012" type="box" rgba="0 0 1 0"/>
                                <body name="pandafinger_joint1_tip" pos="0 0.0085 0.056">
                                  <inertial pos="0 0 0" quat="0 0 0 1" mass="0.01" diaginertia="0.01 0.01 0.01"/>
                                  <geom name="pandafinger1_tip_collision" size="0.008 0.004 0.008" pos="0 -0.005 -0.012" quat="0 0 0 1" friction="2 0.05" solref="0.01 0.5" rgba="1 0 0 1"/>
                                </body>
                              </body>
                              <body name="pandapanda_rightfinger" childclass="pandapanda:gripper" pos="0 0 0.0584">
                                <inertial pos="2.42335e-05 -0.0119585 0.0237816" quat="0.996177 -0.0868631 2.79377e-05 -0.00926642" mass="0.0218754" diaginertia="5.69661e-06 5.56035e-06 1.55183e-06"/>
                                <joint name="pandapanda_finger_joint2" pos="0 0 0" axis="0 -1 0"/>
                                <geom name="pandapanda_rightfinger:geom1" quat="0 0 0 1" type="mesh" contype="0" conaffinity="0" group="1" mesh="pandafingerv"/>
                                <geom name="pandapanda_rightfinger:geom2" quat="0 0 0 1" type="mesh" mesh="pandafingerv"/>
                                <site name="pandapanda_rightfinger:site" pos="0 -0.012 0.045" size="0.012 0.015 0.012" type="box" rgba="0 0 1 0"/>
                                <body name="pandafinger_joint2_tip" pos="0 -0.0085 0.056">
                                  <inertial pos="0 0 0" quat="0 0 0 1" mass="0.01" diaginertia="0.01 0.01 0.01"/>
                                  <geom name="pandafinger2_tip_collision" size="0.008 0.004 0.008" pos="0 0.005 -0.012" quat="0 0 0 1" friction="2 0.05" solref="0.01 0.5" rgba="1 0 0 1"/>
                                </body>
                              </body>
                            </body>
                          </body>
                        </body>
                      </body>
                    </body>
                  </body>
                </body>
              </body>
            </body>
          </body>
        </body>
      </body>
    </body>
  </worldbody>

  <contact>
    <exclude body1="pandapanda_link0" body2="pandapanda_link1"/>
    <exclude body1="pandapanda_link1" body2="pandapanda_link2"/>
    <exclude body1="pandapanda_link2" body2="pandapanda_link3"/>
    <exclude body1="pandapanda_link3" body2="pandapanda_link4"/>
    <exclude body1="pandapanda_link4" body2="pandapanda_link5"/>
    <exclude body1="pandapanda_link5" body2="pandapanda_link6"/>
    <exclude body1="pandapanda_link6" body2="pandapanda_link7"/>
    <exclude body1="pandapanda_link7" body2="pandapanda_link8"/>
    <exclude body1="pandapanda_link8" body2="pandapanda_hand"/>
  </contact>

  <actuator>
    <general name="pandapanda_joint1_act" joint="pandapanda_joint1" forcelimited="true" forcerange="-87 87"/>
    <general name="pandapanda_joint2_act" joint="pandapanda_joint2" forcelimited="true" forcerange="-87 87"/>
    <general name="pandapanda_joint3_act" joint="pandapanda_joint3" forcelimited="true" forcerange="-87 87"/>
    <general name="pandapanda_joint4_act" joint="pandapanda_joint4" forcelimited="true" forcerange="-87 87"/>
    <general name="pandapanda_joint5_act" joint="pandapanda_joint5" forcelimited="true" forcerange="-12 12"/>
    <general name="pandapanda_joint6_act" joint="pandapanda_joint6" forcelimited="true" forcerange="-12 12"/>
    <general name="pandapanda_joint7_act" joint="pandapanda_joint7" forcelimited="true" forcerange="-12 12"/>
    <general name="pandapanda_finger_joint1_act" joint="pandapanda_finger_joint1" forcelimited="true" forcerange="-70 70"/>
    <general name="pandapanda_finger_joint2_act" joint="pandapanda_finger_joint2" forcelimited="true" forcerange="-70 70"/>
  </actuator>

  <sensor>
    <touch site="pandapanda_leftfinger:site" name="pandatouchsensor:left"/>
    <touch site="pandapanda_rightfinger:site" name="pandatouchsensor:right"/>
  </sensor>
</mujoco>
